<?xml version="1.0" ?>
<robot name="cycloidal_arm" xmlns:xacro="http://www.ros.org/wiki/xacro">

<xacro:include filename="$(find cycloidal_arm)/urdf/materials.xacro" />


<link name="base_link">
  <inertial>
    <origin xyz="0.011250081392468421 -3.307759790897504e-06 0.02096005715733511" rpy="0 0 0"/>
    <mass value="1.1434563677530065"/>
    <inertia ixx="0.002559" iyy="0.003586" izz="0.005736" ixy="-0.0" iyz="0.0" ixz="-5.2e-05"/>
  </inertial>
  <visual>
    <origin xyz="0 0 0" rpy="0 0 0"/>
    <geometry>
      <mesh filename="package://cycloidal_arm/meshes/base_link.stl" scale="0.001 0.001 0.001"/>
    </geometry>
    <material name="silver"/>
  </visual>
  <collision>
    <origin xyz="0 0 0" rpy="0 0 0"/>
    <geometry>
      <mesh filename="package://cycloidal_arm/meshes/base_link.stl" scale="0.001 0.001 0.001"/>
    </geometry>
  </collision>
</link>

<link name="link_1_1">
  <inertial>
    <origin xyz="2.785423607376964e-17 -1.5319829840573303e-15 0.03284853130132172" rpy="0 0 0"/>
    <mass value="0.6922210189689346"/>
    <inertia ixx="0.00133" iyy="0.001397" izz="0.001299" ixy="0.0" iyz="0.0" ixz="0.0"/>
  </inertial>
  <visual>
    <origin xyz="-0.0 -0.0 -0.03" rpy="0 0 0"/>
    <geometry>
      <mesh filename="package://cycloidal_arm/meshes/link_1_1.stl" scale="0.001 0.001 0.001"/>
    </geometry>
    <material name="silver"/>
  </visual>
  <collision>
    <origin xyz="-0.0 -0.0 -0.03" rpy="0 0 0"/>
    <geometry>
      <mesh filename="package://cycloidal_arm/meshes/link_1_1.stl" scale="0.001 0.001 0.001"/>
    </geometry>
  </collision>
</link>

<link name="link_2_1">
  <inertial>
    <origin xyz="-0.04000000000000001 -1.6058763459881033e-05 0.09471209008925147" rpy="0 0 0"/>
    <mass value="0.7128365952218098"/>
    <inertia ixx="0.008572" iyy="0.008566" izz="0.000471" ixy="-0.0" iyz="-0.0" ixz="-0.0"/>
  </inertial>
  <visual>
    <origin xyz="-0.037148 0.0 -0.14518" rpy="0 0 0"/>
    <geometry>
      <mesh filename="package://cycloidal_arm/meshes/link_2_1.stl" scale="0.001 0.001 0.001"/>
    </geometry>
    <material name="silver"/>
  </visual>
  <collision>
    <origin xyz="-0.037148 0.0 -0.14518" rpy="0 0 0"/>
    <geometry>
      <mesh filename="package://cycloidal_arm/meshes/link_2_1.stl" scale="0.001 0.001 0.001"/>
    </geometry>
  </collision>
</link>

<link name="link_3_1">
  <inertial>
    <origin xyz="-0.03999979461983164 -4.10877760374522e-06 0.036295042070174754" rpy="0 0 0"/>
    <mass value="0.5220823279917146"/>
    <inertia ixx="0.001597" iyy="0.001522" izz="0.000285" ixy="-0.0" iyz="0.0" ixz="-0.0"/>
  </inertial>
  <visual>
    <origin xyz="-0.034338 -0.0 -0.446144" rpy="0 0 0"/>
    <geometry>
      <mesh filename="package://cycloidal_arm/meshes/link_3_1.stl" scale="0.001 0.001 0.001"/>
    </geometry>
    <material name="silver"/>
  </visual>
  <collision>
    <origin xyz="-0.034338 -0.0 -0.446144" rpy="0 0 0"/>
    <geometry>
      <mesh filename="package://cycloidal_arm/meshes/link_3_1.stl" scale="0.001 0.001 0.001"/>
    </geometry>
  </collision>
</link>

<link name="link_4_1">
  <inertial>
    <origin xyz="2.0572304345115033e-07 -1.862792863760201e-10 0.02013378523502929" rpy="0 0 0"/>
    <mass value="0.0712412387691247"/>
    <inertia ixx="5e-05" iyy="0.000214" izz="0.000193" ixy="-0.0" iyz="0.0" ixz="-0.0"/>
  </inertial>
  <visual>
    <origin xyz="0.005662 0.0 -0.611106" rpy="0 0 0"/>
    <geometry>
      <mesh filename="package://cycloidal_arm/meshes/link_4_1.stl" scale="0.001 0.001 0.001"/>
    </geometry>
    <material name="silver"/>
  </visual>
  <collision>
    <origin xyz="0.005662 0.0 -0.611106" rpy="0 0 0"/>
    <geometry>
      <mesh filename="package://cycloidal_arm/meshes/link_4_1.stl" scale="0.001 0.001 0.001"/>
    </geometry>
  </collision>
</link>

<link name="link_5_1">
  <inertial>
    <origin xyz="-0.05999979427694806 -1.8626450485028255e-10 1.6900727961566275e-07" rpy="0 0 0"/>
    <mass value="0.16139766351321969"/>
    <inertia ixx="8e-05" iyy="0.000145" izz="0.000214" ixy="0.0" iyz="0.0" ixz="0.0"/>
  </inertial>
  <visual>
    <origin xyz="-0.054338 0.0 -0.657106" rpy="0 0 0"/>
    <geometry>
      <mesh filename="package://cycloidal_arm/meshes/link_5_1.stl" scale="0.001 0.001 0.001"/>
    </geometry>
    <material name="silver"/>
  </visual>
  <collision>
    <origin xyz="-0.054338 0.0 -0.657106" rpy="0 0 0"/>
    <geometry>
      <mesh filename="package://cycloidal_arm/meshes/link_5_1.stl" scale="0.001 0.001 0.001"/>
    </geometry>
  </collision>
</link>

<link name="camera_1">
  <inertial>
    <origin xyz="2.0572305194262175e-07 -1.8626450639658287e-10 0.010000169005066062" rpy="0 0 0"/>
    <mass value="0.301"/>
    <inertia ixx="7.3e-05" iyy="7.3e-05" izz="0.000125" ixy="0.0" iyz="-0.0" ixz="-0.0"/>
  </inertial>
  <visual>
    <origin xyz="0.005662 0.0 -0.667106" rpy="0 0 0"/>
    <geometry>
      <mesh filename="package://cycloidal_arm/meshes/camera_1.stl" scale="0.001 0.001 0.001"/>
    </geometry>
    <material name="silver"/>
  </visual>
  <collision>
    <origin xyz="0.005662 0.0 -0.667106" rpy="0 0 0"/>
    <geometry>
      <mesh filename="package://cycloidal_arm/meshes/camera_1.stl" scale="0.001 0.001 0.001"/>
    </geometry>
  </collision>
</link>

<joint name="Revolute_1" type="continuous">
  <origin xyz="0.0 0.0 0.03" rpy="0 0 0"/>
  <parent link="base_link"/>
  <child link="link_1_1"/>
  <axis xyz="0.0 0.0 1.0"/>
</joint>

<joint name="Revolute_2" type="continuous">
  <origin xyz="0.037148 -0.0 0.11518" rpy="0 0 0"/>
  <parent link="link_1_1"/>
  <child link="link_2_1"/>
  <axis xyz="-1.0 0.0 0.0"/>
</joint>

<joint name="Revolute_3" type="continuous">
  <origin xyz="-0.00281 0.0 0.300964" rpy="0 0 0"/>
  <parent link="link_2_1"/>
  <child link="link_3_1"/>
  <axis xyz="1.0 0.0 0.0"/>
</joint>

<joint name="Revolute_4" type="continuous">
  <origin xyz="-0.04 -0.0 0.164962" rpy="0 0 0"/>
  <parent link="link_3_1"/>
  <child link="link_4_1"/>
  <axis xyz="0.0 0.0 1.0"/>
</joint>

<joint name="Revolute_5" type="continuous">
  <origin xyz="0.06 0.0 0.046" rpy="0 0 0"/>
  <parent link="link_4_1"/>
  <child link="link_5_1"/>
  <axis xyz="-1.0 0.0 0.0"/>
</joint>

<joint name="Rigid 6" type="fixed">
  <origin xyz="-0.06 0.0 0.01" rpy="0 0 0"/>
  <parent link="link_5_1"/>
  <child link="camera_1"/>
</joint>

<xacro:include filename="$(find cycloidal_arm)/urdf/arm_trans.xacro" />
<xacro:include filename="$(find cycloidal_arm)/urdf/arm_controller.xacro" />
</robot>